File: PB2_Astr_0.05%_20K.txt
#EXPORTTYPE:DATA SINGLE
#FILE:2023-12-26_PB2_Astr_0.05%_liquid_v1_25-225_20Kmin_100mlmin.ngb-sd7
#FORMAT:NETZSCH5
#FTYPE:ANSI
#IDENTITY:PB2_Astr_0.05%_liquid_v1
#DECIMAL:POINT
#SEPARATOR:SEMICOLON
#MTYPE:DSC
#INSTRUMENT:NETZSCH DSC 204F1 Phoenix
#PROJECT:
#DATE/TIME:26.12.2023 10:09
#CORR. FILE:
#TEMPCAL:17-12-2021 14:16
#SENSITIVITY:17-12-2021 14:03
#LABORATORY:
#OPERATOR:SitnikovaV
#REMARK:
#SAMPLE:PB2_Astr_0.05%_liquid_v1
#SAMPLE MASS /mg:22,302
#MATERIAL:
#REFERENCE:ÏÂÑ ïîðîøîê
#REFERENCE MASS /mg:0
#TYPE OF CRUCIBLE:Concavus Al, closed
#SAMPLE CRUCIBLE MASS /mg:0
#REFERENCE CRUCIBLE MASS /mg:0
#PURGE 1 MFC:OXYGEN,252,5 ml/min
#PURGE 2 MFC:NITROGEN,250,0 ml/min
#PROTECTIVE MFC:NITROGEN,250,0 ml/min
#M.RANGE /µV:5000
#TAU-R:---
#CORR. CODE:000
#EXO:-1
#RANGE:25°C/20.0(K/min)/225°C
#SEGMENT:S1/1
#SEG. 1:25°C/20.0(K/min)/225°C

##Temp./°C;Time/min;DSC/(mW/mg);Sensit./(uV/mW)
 23.99600;0.00000; 2.818984e-02;3.39243
 24.99600;0.16287;      0.11856;3.39211
 25.99600;0.22890;      0.24610;3.39178
 26.99600;0.28344;      0.36291;3.39144
 27.99600;0.33303;      0.46550;3.39109
 28.99600;0.38005;      0.55409;3.39073
 29.99600;0.42559;      0.62892;3.39036
 30.99600;0.47025;      0.69160;3.38998
 31.99600;0.51437;      0.74368;3.38959
 32.99600;0.55816;      0.78674;3.38919
 33.99600;0.60179;      0.82186;3.38878
 34.99600;0.64533;      0.85029;3.38836
 35.99600;0.68888;      0.87342;3.38793
 36.99600;0.73248;      0.89208;3.38750
 37.99600;0.77619;      0.90665;3.38705
 38.99600;0.82005;      0.91846;3.38659
 39.99600;0.86407;      0.92745;3.38612
 40.99600;0.90827;      0.93424;3.38564
 41.99600;0.95269;      0.93949;3.38515
 42.99600;0.99733;      0.94286;3.38465
 43.99600;1.04222;      0.94505;3.38414
 44.99600;1.08733;      0.94603;3.38362
 45.99600;1.13269;      0.94648;3.38309
 46.99600;1.17829;      0.94635;3.38255
 47.99600;1.22413;      0.94544;3.38200
 48.99600;1.27021;      0.94420;3.38144
 49.99600;1.31652;      0.94242;3.38087
 50.99600;1.36307;      0.94056;3.38029
 51.99600;1.40985;      0.93875;3.37970
 52.99600;1.45685;      0.93656;3.37910
 53.99600;1.50406;      0.93449;3.37849
 54.99600;1.55146;      0.93239;3.37787
 55.99600;1.59906;      0.93030;3.37724
 56.99600;1.64684;      0.92843;3.37660
 57.99600;1.69477;      0.92648;3.37595
 58.99600;1.74286;      0.92480;3.37530
 59.99600;1.79111;      0.92315;3.37463
 60.99600;1.83949;      0.92161;3.37395
 61.99600;1.88801;      0.92025;3.37326
 62.99600;1.93666;      0.91898;3.37256
 63.99600;1.98539;      0.91794;3.37185
 64.99600;2.03420;      0.91718;3.37114
 65.99600;2.08308;      0.91635;3.37041
 66.99600;2.13205;      0.91593;3.36967
 67.99600;2.18109;      0.91547;3.36892
 68.99600;2.23019;      0.91539;3.36816
 69.99600;2.27932;      0.91510;3.36740
 70.99600;2.32850;      0.91498;3.36662
 71.99600;2.37770;      0.91497;3.36583
 72.99600;2.42693;      0.91540;3.36504
 73.99600;2.47618;      0.91590;3.36423
 74.99600;2.52545;      0.91607;3.36341
 75.99600;2.57477;      0.91662;3.36259
 76.99600;2.62413;      0.91695;3.36175
 77.99600;2.67350;      0.91743;3.36091
 78.99600;2.72287;      0.91795;3.36005
 79.99600;2.77226;      0.91861;3.35918
 80.99600;2.82166;      0.91942;3.35831
 81.99600;2.87105;      0.92013;3.35743
 82.99600;2.92042;      0.92081;3.35653
 83.99600;2.96982;      0.92160;3.35563
 84.99600;3.01924;      0.92246;3.35471
 85.99600;3.06868;      0.92297;3.35379
 86.99600;3.11815;      0.92370;3.35286
 87.99600;3.16762;      0.92443;3.35191
 88.99600;3.21707;      0.92523;3.35096
 89.99600;3.26654;      0.92593;3.35000
 90.99600;3.31603;      0.92666;3.34903
 91.99600;3.36553;      0.92719;3.34804
 92.99600;3.41506;      0.92792;3.34705
 93.99600;3.46462;      0.92840;3.34605
 94.99600;3.51420;      0.92891;3.34504
 95.99600;3.56379;      0.92948;3.34402
 96.99600;3.61337;      0.93025;3.34299
 97.99600;3.66298;      0.93100;3.34195
 98.99600;3.71260;      0.93160;3.34090
 99.99600;3.76223;      0.93226;3.33984
100.99600;3.81186;      0.93304;3.33877
101.99600;3.86148;      0.93381;3.33770
102.99600;3.91111;      0.93467;3.33661
103.99600;3.96073;      0.93535;3.33551
104.99600;4.01035;      0.93619;3.33440
105.99600;4.05998;      0.93710;3.33329
106.99600;4.10962;      0.93777;3.33216
107.99600;4.15929;      0.93835;3.33103
108.99600;4.20898;      0.93915;3.32988
109.99600;4.25867;      0.93978;3.32873
110.99600;4.30837;      0.94053;3.32756
111.99600;4.35807;      0.94108;3.32639
112.99600;4.40778;      0.94188;3.32521
113.99600;4.45747;      0.94248;3.32401
114.99600;4.50714;      0.94314;3.32281
115.99600;4.55681;      0.94407;3.32160
116.99600;4.60648;      0.94479;3.32038
117.99600;4.65614;      0.94544;3.31915
118.99600;4.70579;      0.94604;3.31791
119.99600;4.75543;      0.94670;3.31666
120.99600;4.80507;      0.94729;3.31540
121.99600;4.85470;      0.94803;3.31414
122.99600;4.90431;      0.94860;3.31286
123.99600;4.95392;      0.94907;3.31157
124.99600;5.00351;      0.94943;3.31028
125.99600;5.05310;      0.94979;3.30897
126.99600;5.10275;      0.94984;3.30766
127.99600;5.15244;      0.94941;3.30633
128.99600;5.20213;      0.94803;3.30500
129.99600;5.25182;      0.94534;3.30366
130.99600;5.30153;      0.94189;3.30231
131.99600;5.35126;      0.93702;3.30094
132.99600;5.40097;      0.93138;3.29957
133.99600;5.45069;      0.92442;3.29819
134.99600;5.50042;      0.91621;3.29681
135.99600;5.55013;      0.90576;3.29541
136.99600;5.59982;      0.89166;3.29400
137.99600;5.64950;      0.86786;3.29258
138.99600;5.69920;      0.82976;3.29116
139.99600;5.74891;      0.79971;3.28972
140.99600;5.79862;      0.77725;3.28828
141.99600;5.84834;      0.75891;3.28683
142.99600;5.89807;      0.74170;3.28536
143.99600;5.94782;      0.72387;3.28389
144.99600;5.99759;      0.70377;3.28241
145.99600;6.04739;      0.67973;3.28092
146.99600;6.09720;      0.65080;3.27942
147.99600;6.14702;      0.61631;3.27791
148.99600;6.19687;      0.57491;3.27640
149.99600;6.24673;      0.52518;3.27487
150.99600;6.29661;      0.46571;3.27334
151.99600;6.34650;      0.39407;3.27179
152.99600;6.39638;      0.30737;3.27024
153.99600;6.44627;      0.20097;3.26868
154.99600;6.49616; 6.773331e-02;3.26711
155.99600;6.54607;     -0.10148;3.26553
156.99600;6.59597;     -0.30983;3.26394
157.99600;6.64584;     -0.53101;3.26234
158.99600;6.69570;     -0.74284;3.26073
159.99600;6.74555;     -0.94674;3.25911
160.99600;6.79540;     -1.14125;3.25749
161.99600;6.84527;     -1.32044;3.25586
162.99600;6.89513;     -1.47957;3.25421
163.99600;6.94498;     -1.61394;3.25256
164.99600;6.99485;     -1.72093;3.25090
165.99600;7.04474;     -1.79791;3.24923
166.99600;7.09465;     -1.84479;3.24755
167.99600;7.14455;     -1.86198;3.24587
168.99600;7.19445;     -1.85111;3.24417
169.99600;7.24435;     -1.81512;3.24246
170.99600;7.29426;     -1.75681;3.24075
171.99600;7.34417;     -1.67953;3.23903
172.99600;7.39407;     -1.58723;3.23730
173.99600;7.44397;     -1.48444;3.23556
174.99600;7.49390;     -1.37659;3.23381
175.99600;7.54385;     -1.26778;3.23205
176.99600;7.59381;     -1.16458;3.23029
177.99600;7.64376;     -1.07027;3.22851
178.99600;7.69371;     -0.98675;3.22673
179.99600;7.74367;     -0.91509;3.22494
180.99600;7.79364;     -0.85531;3.22314
181.99600;7.84360;     -0.80665;3.22133
182.99600;7.89355;     -0.76742;3.21951
183.99600;7.94350;     -0.73628;3.21768
184.99600;7.99346;     -0.71159;3.21585
185.99600;8.04343;     -0.69193;3.21400
186.99600;8.09340;     -0.67576;3.21215
187.99600;8.14339;     -0.66111;3.21029
188.99600;8.19339;     -0.64638;3.20842
189.99600;8.24339;     -0.63085;3.20654
190.99600;8.29338;     -0.61316;3.20466
191.99600;8.34340;     -0.59207;3.20276
192.99600;8.39345;     -0.56699;3.20086
193.99600;8.44350;     -0.53740;3.19895
194.99600;8.49356;     -0.50292;3.19703
195.99600;8.54362;     -0.46284;3.19510
196.99600;8.59370;     -0.41764;3.19316
197.99600;8.64379;     -0.36698;3.19122
198.99600;8.69389;     -0.31175;3.18926
199.99600;8.74400;     -0.25200;3.18730
200.99600;8.79411;     -0.18817;3.18533
201.99600;8.84421;     -0.12078;3.18335
202.99600;8.89430;-5.049821e-02;3.18136
203.99600;8.94438; 2.202299e-02;3.17937
204.99600;8.99446; 9.618403e-02;3.17737
205.99600;9.04452;      0.17097;3.17535
206.99600;9.09457;      0.24628;3.17333
207.99600;9.14462;      0.32059;3.17131
208.99600;9.19468;      0.39374;3.16927
209.99600;9.24474;      0.46522;3.16722
210.99600;9.29479;      0.53433;3.16517
211.99600;9.34484;      0.60059;3.16311
212.99600;9.39489;      0.66345;3.16104
213.99600;9.44493;      0.72312;3.15896
214.99600;9.49496;      0.77917;3.15688
215.99600;9.54497;      0.83127;3.15478
216.99600;9.59498;      0.87951;3.15268
217.99600;9.64500;      0.92359;3.15057
218.99600;9.69500;      0.96412;3.14846
219.99600;9.74500;      1.00055;3.14633
220.99600;9.79500;      1.03351;3.14420
221.99600;9.84503;      1.06300;3.14205
222.99600;9.89506;      1.08922;3.13991
223.99600;9.94508;      1.11270;3.13775
224.99600;9.99511;      1.13363;3.13558