File: PB2_Astr_0.05%_5K.txt
#EXPORTTYPE:DATA SINGLE
#FILE:2023-12-26_PB2_Astr_0.05%_liquid_v1_25-225_5Kmin_100mlmin.ngb-sd7
#FORMAT:NETZSCH5
#FTYPE:ANSI
#IDENTITY:PB2_Astr_0.05%_liquid
#DECIMAL:POINT
#SEPARATOR:SEMICOLON
#MTYPE:DSC
#INSTRUMENT:NETZSCH DSC 204F1 Phoenix
#PROJECT:
#DATE/TIME:26.12.2023 12:12
#CORR. FILE:
#TEMPCAL:17-12-2021 14:12
#SENSITIVITY:17-12-2021 13:58
#LABORATORY:
#OPERATOR:SitnikovaV
#REMARK:
#SAMPLE:PB2_Astr_0.05%_liquid
#SAMPLE MASS /mg:44,360
#MATERIAL:
#REFERENCE:ÏÂÑ ïîðîøîê
#REFERENCE MASS /mg:0
#TYPE OF CRUCIBLE:Concavus Al, closed
#SAMPLE CRUCIBLE MASS /mg:0
#REFERENCE CRUCIBLE MASS /mg:0
#PURGE 1 MFC:OXYGEN,252,5 ml/min
#PURGE 2 MFC:NITROGEN,250,0 ml/min
#PROTECTIVE MFC:NITROGEN,250,0 ml/min
#M.RANGE /µV:5000
#TAU-R:---
#CORR. CODE:000
#EXO:-1
#RANGE:25°C/5.0(K/min)/225°C
#SEGMENT:S1/1
#SEG. 1:25°C/5.0(K/min)/225°C

##Temp./°C;Time/min;DSC/(mW/mg);Sensit./(uV/mW)
 24.93200; 0.00000; 1.341018e-03;3.45047
 25.93200; 0.31870; 8.007528e-02;3.45102
 26.93200; 0.51667;      0.14860;3.45153
 27.93200; 0.69764;      0.18450;3.45203
 28.93200; 0.87704;      0.20283;3.45249
 29.93200; 1.05863;      0.21058;3.45293
 30.93200; 1.24356;      0.21284;3.45334
 31.93200; 1.43199;      0.21198;3.45372
 32.93200; 1.62350;      0.21000;3.45407
 33.93200; 1.81738;      0.20779;3.45440
 34.93200; 2.01297;      0.20605;3.45470
 35.93200; 2.20978;      0.20483;3.45498
 36.93200; 2.40740;      0.20377;3.45523
 37.93200; 2.60546;      0.20332;3.45545
 38.93200; 2.80383;      0.20293;3.45564
 39.93200; 3.00251;      0.20279;3.45581
 40.93200; 3.20128;      0.20282;3.45595
 41.93200; 3.39992;      0.20303;3.45606
 42.93200; 3.59859;      0.20326;3.45615
 43.93200; 3.79746;      0.20328;3.45621
 44.93200; 3.99648;      0.20328;3.45624
 45.93200; 4.19549;      0.20335;3.45625
 46.93200; 4.39440;      0.20364;3.45624
 47.93200; 4.59320;      0.20390;3.45619
 48.93200; 4.79206;      0.20414;3.45612
 49.93200; 4.99123;      0.20409;3.45603
 50.93200; 5.19075;      0.20396;3.45591
 51.93200; 5.39045;      0.20397;3.45576
 52.93200; 5.59026;      0.20402;3.45559
 53.93200; 5.79014;      0.20413;3.45539
 54.93200; 5.98993;      0.20426;3.45516
 55.93200; 6.18947;      0.20458;3.45491
 56.93200; 6.38890;      0.20502;3.45464
 57.93200; 6.58849;      0.20514;3.45434
 58.93200; 6.78827;      0.20515;3.45401
 59.93200; 6.98813;      0.20527;3.45366
 60.93200; 7.18807;      0.20531;3.45329
 61.93200; 7.38810;      0.20548;3.45288
 62.93200; 7.58817;      0.20563;3.45246
 63.93200; 7.78828;      0.20567;3.45201
 64.93200; 7.98824;      0.20589;3.45153
 65.93200; 8.18792;      0.20622;3.45103
 66.93200; 8.38734;      0.20669;3.45051
 67.93200; 8.58680;      0.20709;3.44996
 68.93200; 8.78656;      0.20684;3.44939
 69.93200; 8.98655;      0.20681;3.44879
 70.93200; 9.18658;      0.20697;3.44817
 71.93200; 9.38671;      0.20694;3.44752
 72.93200; 9.58694;      0.20695;3.44685
 73.93200; 9.78726;      0.20706;3.44616
 74.93200; 9.98766;      0.20704;3.44544
 75.93200;10.18803;      0.20725;3.44470
 76.93200;10.38822;      0.20742;3.44394
 77.93200;10.58810;      0.20784;3.44315
 78.93200;10.78774;      0.20818;3.44234
 79.93200;10.98720;      0.20867;3.44150
 80.93200;11.18657;      0.20894;3.44064
 81.93200;11.38594;      0.20921;3.43976
 82.93200;11.58540;      0.20932;3.43886
 83.93200;11.78491;      0.20945;3.43793
 84.93200;11.98456;      0.20947;3.43698
 85.93200;12.18451;      0.20933;3.43601
 86.93200;12.38465;      0.20916;3.43501
 87.93200;12.58465;      0.20910;3.43400
 88.93200;12.78437;      0.20937;3.43296
 89.93200;12.98399;      0.20990;3.43189
 90.93200;13.18390;      0.20981;3.43081
 91.93200;13.38414;      0.20969;3.42970
 92.93200;13.58452;      0.20954;3.42857
 93.93200;13.78487;      0.20949;3.42742
 94.93200;13.98521;      0.20945;3.42625
 95.93200;14.18562;      0.20926;3.42506
 96.93200;14.38606;      0.20940;3.42384
 97.93200;14.58642;      0.20967;3.42260
 98.93200;14.78671;      0.20964;3.42135
 99.93200;14.98699;      0.20939;3.42007
100.93200;15.18718;      0.20884;3.41877
101.93200;15.38725;      0.20844;3.41744
102.93200;15.58720;      0.20788;3.41610
103.93200;15.78686;      0.20715;3.41474
104.93200;15.98578;      0.20638;3.41335
105.93200;16.18387;      0.20600;3.41195
106.93200;16.38184;      0.20501;3.41052
107.93200;16.58055;      0.20300;3.40908
108.93200;16.78023;      0.20036;3.40761
109.93200;16.98068;      0.19750;3.40613
110.93200;17.18152;      0.19500;3.40462
111.93200;17.38234;      0.19244;3.40309
112.93200;17.58295;      0.19038;3.40155
113.93200;17.78334;      0.18864;3.39998
114.93200;17.98349;      0.18686;3.39840
115.93200;18.18335;      0.18550;3.39679
116.93200;18.38291;      0.18455;3.39517
117.93200;18.58231;      0.18347;3.39353
118.93200;18.78179;      0.18147;3.39187
119.93200;18.98144;      0.17952;3.39019
120.93200;19.18125;      0.17759;3.38849
121.93200;19.38111;      0.17543;3.38677
122.93200;19.58076;      0.17257;3.38503
123.93200;19.78013;      0.16827;3.38327
124.93200;19.97956;      0.16506;3.38150
125.93200;20.17954;      0.16093;3.37971
126.93200;20.38025;      0.15495;3.37790
127.93200;20.58124;      0.14801;3.37607
128.93200;20.78191;      0.14017;3.37422
129.93200;20.98209;      0.13114;3.37236
130.93200;21.18185;      0.11968;3.37048
131.93200;21.38135;      0.10589;3.36858
132.93200;21.58085; 8.897711e-02;3.36666
133.93200;21.78069; 6.767193e-02;3.36473
134.93200;21.98098; 4.072158e-02;3.36278
135.93200;22.18165; 6.786503e-03;3.36081
136.93200;22.38246;-3.677733e-02;3.35883
137.93200;22.58291;-9.316772e-02;3.35683
138.93200;22.78267;     -0.16384;3.35481
139.93200;22.98192;     -0.24320;3.35277
140.93200;23.18115;     -0.31435;3.35072
141.93200;23.38060;     -0.37203;3.34866
142.93200;23.58031;     -0.42537;3.34657
143.93200;23.78032;     -0.47877;3.34447
144.93200;23.98068;     -0.53018;3.34236
145.93200;24.18123;     -0.57569;3.34023
146.93200;24.38162;     -0.61203;3.33808
147.93200;24.58155;     -0.63707;3.33592
148.93200;24.78118;     -0.64989;3.33374
149.93200;24.98086;     -0.65081;3.33155
150.93200;25.18070;     -0.64073;3.32934
151.93200;25.38071;     -0.62171;3.32712
152.93200;25.58094;     -0.59596;3.32488
153.93200;25.78119;     -0.56577;3.32263
154.93200;25.98123;     -0.53235;3.32036
155.93200;26.18113;     -0.49792;3.31808
156.93200;26.38101;     -0.46326;3.31578
157.93200;26.58086;     -0.42918;3.31347
158.93200;26.78072;     -0.39661;3.31115
159.93200;26.98070;     -0.36740;3.30881
160.93200;27.18078;     -0.34240;3.30646
161.93200;27.38090;     -0.32216;3.30409
162.93200;27.58099;     -0.30693;3.30171
163.93200;27.78094;     -0.29551;3.29932
164.93200;27.98071;     -0.28705;3.29691
165.93200;28.18044;     -0.28097;3.29449
166.93200;28.38008;     -0.27564;3.29206
167.93200;28.57957;     -0.27039;3.28961
168.93200;28.77919;     -0.26534;3.28716
169.93200;28.97904;     -0.25924;3.28469
170.93200;29.17900;     -0.25152;3.28220
171.93200;29.37899;     -0.24216;3.27971
172.93200;29.57899;     -0.23071;3.27720
173.93200;29.77884;     -0.21711;3.27468
174.93200;29.97860;     -0.20130;3.27215
175.93200;30.17853;     -0.18375;3.26960
176.93200;30.37873;     -0.16443;3.26705
177.93200;30.57908;     -0.14375;3.26448
178.93200;30.77942;     -0.12123;3.26190
179.93200;30.97982;-9.768344e-02;3.25931
180.93200;31.18031;-7.337213e-02;3.25671
181.93200;31.38065;-4.814277e-02;3.25409
182.93200;31.58064;-2.256170e-02;3.25147
183.93200;31.78042; 2.832825e-03;3.24884
184.93200;31.98016; 2.786534e-02;3.24619
185.93200;32.17993; 5.225258e-02;3.24353
186.93200;32.37980; 7.582256e-02;3.24087
187.93200;32.57972; 9.807576e-02;3.23819
188.93200;32.77964;      0.11931;3.23550
189.93200;32.97961;      0.13922;3.23281
190.93200;33.17975;      0.15748;3.23010
191.93200;33.38002;      0.17404;3.22738
192.93200;33.58038;      0.18924;3.22466
193.93200;33.78081;      0.20258;3.22192
194.93200;33.98115;      0.21454;3.21918
195.93200;34.18108;      0.22549;3.21642
196.93200;34.38064;      0.23518;3.21366
197.93200;34.58015;      0.24329;3.21088
198.93200;34.77979;      0.25022;3.20810
199.93200;34.97961;      0.25588;3.20531
200.93200;35.17960;      0.26088;3.20251
201.93200;35.37967;      0.26497;3.19971
202.93200;35.57973;      0.26887;3.19689
203.93200;35.77985;      0.27228;3.19407
204.93200;35.98011;      0.27513;3.19123
205.93200;36.18029;      0.27768;3.18839
206.93200;36.38016;      0.28033;3.18554
207.93200;36.57974;      0.28270;3.18269
208.93200;36.77929;      0.28478;3.17983
209.93200;36.97900;      0.28665;3.17695
210.93200;37.17889;      0.28810;3.17408
211.93200;37.37887;      0.28939;3.17119
212.93200;37.57892;      0.29076;3.16830
213.93200;37.77915;      0.29192;3.16540
214.93200;37.97954;      0.29259;3.16249
215.93200;38.17980;      0.29344;3.15958
216.93200;38.37975;      0.29459;3.15666
217.93200;38.57953;      0.29543;3.15373
218.93200;38.77934;      0.29585;3.15080
219.93200;38.97921;      0.29613;3.14786
220.93200;39.17902;      0.29642;3.14492
221.93200;39.37874;      0.29660;3.14197
222.93200;39.57839;      0.29669;3.13901
223.93200;39.77808;      0.29650;3.13605
224.93200;39.97790;      0.29614;3.13308