File: data/PB2_Astr_0.05%_3K.txt
#EXPORTTYPE:DATA SINGLE
#FILE:2023-12-26_PB2_Astr_0.05%_liquid_v1_25-225_3Kmin_100mlmin.ngb-sd7
#FORMAT:NETZSCH5
#FTYPE:ANSI
#IDENTITY:PB2_Astr_0.05%_liquid
#DECIMAL:POINT
#SEPARATOR:SEMICOLON
#MTYPE:DSC
#INSTRUMENT:NETZSCH DSC 204F1 Phoenix
#PROJECT:
#DATE/TIME:26.12.2023 10:56
#CORR. FILE:
#TEMPCAL:17-12-2021 14:10
#SENSITIVITY:17-12-2021 13:53
#LABORATORY:
#OPERATOR:SitnikovaV
#REMARK:
#SAMPLE:PB2_Astr_0.05%_liquid
#SAMPLE MASS /mg:20,530
#MATERIAL:
#REFERENCE:ÏÂÑ ïîðîøîê
#REFERENCE MASS /mg:0
#TYPE OF CRUCIBLE:Concavus Al, closed
#SAMPLE CRUCIBLE MASS /mg:0
#REFERENCE CRUCIBLE MASS /mg:0
#PURGE 1 MFC:OXYGEN,252,5 ml/min
#PURGE 2 MFC:NITROGEN,250,0 ml/min
#PROTECTIVE MFC:NITROGEN,250,0 ml/min
#M.RANGE /µV:5000
#TAU-R:---
#CORR. CODE:000
#EXO:-1
#RANGE:25°C/3.0(K/min)/225°C
#SEGMENT:S1/1
#SEG. 1:25°C/3.0(K/min)/225°C

##Temp./°C;Time/min;DSC/(mW/mg);Sensit./(uV/mW)
 25.09211; 0.00000;-5.088360e-04;3.44331
 26.09211; 0.44824; 9.498654e-02;3.44408
 27.09211; 0.76815;      0.12925;3.44482
 28.09211; 1.07570;      0.13440;3.44553
 29.09211; 1.38882;      0.13316;3.44621
 30.09211; 1.70969;      0.13092;3.44686
 31.09211; 2.03717;      0.12836;3.44748
 32.09211; 2.36844;      0.12738;3.44808
 33.09211; 2.70089;      0.12738;3.44864
 34.09211; 3.03374;      0.12770;3.44918
 35.09211; 3.36703;      0.12737;3.44969
 36.09211; 3.70043;      0.12757;3.45017
 37.09211; 4.03354;      0.12783;3.45063
 38.09211; 4.36631;      0.12814;3.45105
 39.09211; 4.69903;      0.12833;3.45145
 40.09211; 5.03191;      0.12848;3.45181
 41.09211; 5.36482;      0.12846;3.45215
 42.09211; 5.69756;      0.12875;3.45247
 43.09211; 6.03042;      0.12900;3.45275
 44.09211; 6.36378;      0.12883;3.45301
 45.09211; 6.69750;      0.12891;3.45324
 46.09211; 7.03108;      0.12910;3.45344
 47.09211; 7.36450;      0.12936;3.45361
 48.09211; 7.69806;      0.12916;3.45376
 49.09211; 8.03158;      0.12953;3.45388
 50.09211; 8.36511;      0.12967;3.45397
 51.09211; 8.69904;      0.12938;3.45403
 52.09211; 9.03308;      0.12928;3.45407
 53.09211; 9.36669;      0.12965;3.45408
 54.09211; 9.69979;      0.12991;3.45406
 55.09211;10.03275;      0.13012;3.45402
 56.09211;10.36604;      0.12976;3.45395
 57.09211;10.69965;      0.12983;3.45385
 58.09211;11.03313;      0.12995;3.45373
 59.09211;11.36642;      0.12978;3.45358
 60.09211;11.69985;      0.12991;3.45340
 61.09211;12.03374;      0.12974;3.45319
 62.09211;12.36785;      0.12964;3.45296
 63.09211;12.70180;      0.12957;3.45271
 64.09211;13.03520;      0.12957;3.45242
 65.09211;13.36781;      0.13008;3.45212
 66.09211;13.70042;      0.12999;3.45178
 67.09211;14.03396;      0.12906;3.45142
 68.09211;14.36796;      0.12910;3.45103
 69.09211;14.70152;      0.12913;3.45062
 70.09211;15.03460;      0.12905;3.45018
 71.09211;15.36783;      0.12914;3.44972
 72.09211;15.70145;      0.12848;3.44923
 73.09211;16.03490;      0.12855;3.44871
 74.09211;16.36760;      0.12843;3.44817
 75.09211;16.69968;      0.12868;3.44761
 76.09211;17.03204;      0.12823;3.44702
 77.09211;17.36525;      0.12783;3.44640
 78.09211;17.69902;      0.12723;3.44576
 79.09211;18.03280;      0.12714;3.44510
 80.09211;18.36628;      0.12705;3.44441
 81.09211;18.69973;      0.12664;3.44370
 82.09211;19.03352;      0.12626;3.44296
 83.09211;19.36742;      0.12590;3.44220
 84.09211;19.70085;      0.12582;3.44141
 85.09211;20.03360;      0.12514;3.44060
 86.09211;20.36616;      0.12329;3.43976
 87.09211;20.69913;      0.11832;3.43890
 88.09211;21.03220;      0.11093;3.43802
 89.09211;21.36456;      0.10646;3.43711
 90.09211;21.69680;      0.10446;3.43618
 91.09211;22.02977;      0.10188;3.43523
 92.09211;22.36243;      0.10040;3.43425
 93.09211;22.69425; 9.935335e-02;3.43325
 94.09211;23.02669; 9.695605e-02;3.43222
 95.09211;23.36092; 9.445832e-02;3.43118
 96.09211;23.69640; 9.194523e-02;3.43011
 97.09211;24.03164; 9.042609e-02;3.42901
 98.09211;24.36589; 8.940301e-02;3.42790
 99.09211;24.69944; 8.789567e-02;3.42676
100.09211;25.03258; 8.672170e-02;3.42560
101.09211;25.36544; 8.559128e-02;3.42441
102.09211;25.69809; 8.472919e-02;3.42321
103.09211;26.03053; 8.430660e-02;3.42198
104.09211;26.36306; 8.411488e-02;3.42073
105.09211;26.69616; 8.400343e-02;3.41946
106.09211;27.02945; 8.467585e-02;3.41816
107.09211;27.36204; 8.658617e-02;3.41685
108.09211;27.69414; 8.918864e-02;3.41551
109.09211;28.02635; 9.164365e-02;3.41415
110.09211;28.35813; 9.455288e-02;3.41277
111.09211;28.68934; 9.780601e-02;3.41137
112.09211;29.02125; 9.874599e-02;3.40994
113.09211;29.35487; 9.816000e-02;3.40850
114.09211;29.68996; 9.712204e-02;3.40704
115.09211;30.02546; 9.502968e-02;3.40555
116.09211;30.36034; 9.348031e-02;3.40404
117.09211;30.69450; 9.079660e-02;3.40252
118.09211;31.02842; 8.750965e-02;3.40097
119.09211;31.36267; 8.360225e-02;3.39940
120.09211;31.69731; 7.866956e-02;3.39781
121.09211;32.03104; 7.331114e-02;3.39620
122.09211;32.36288; 6.802998e-02;3.39458
123.09211;32.69344; 5.990505e-02;3.39293
124.09211;33.02402; 5.031259e-02;3.39126
125.09211;33.35671; 3.718925e-02;3.38957
126.09211;33.69210; 1.994015e-02;3.38787
127.09211;34.02759; 1.370130e-03;3.38614
128.09211;34.36122;-2.148370e-02;3.38440
129.09211;34.69345;-4.955631e-02;3.38263
130.09211;35.02541;-7.831183e-02;3.38085
131.09211;35.35808;     -0.10249;3.37905
132.09211;35.69166;     -0.12319;3.37723
133.09211;36.02571;     -0.14312;3.37539
134.09211;36.35989;     -0.16473;3.37353
135.09211;36.69350;     -0.18783;3.37165
136.09211;37.02629;     -0.21148;3.36976
137.09211;37.35935;     -0.23681;3.36785
138.09211;37.69341;     -0.26180;3.36592
139.09211;38.02787;     -0.28592;3.36397
140.09211;38.36143;     -0.30700;3.36200
141.09211;38.69384;     -0.32384;3.36002
142.09211;39.02610;     -0.33762;3.35802
143.09211;39.35836;     -0.34604;3.35600
144.09211;39.69020;     -0.34873;3.35396
145.09211;40.02224;     -0.34759;3.35191
146.09211;40.35543;     -0.34311;3.34984
147.09211;40.68964;     -0.33594;3.34776
148.09211;41.02364;     -0.32563;3.34565
149.09211;41.35634;     -0.31402;3.34354
150.09211;41.68806;     -0.30060;3.34140
151.09211;42.02019;     -0.28666;3.33925
152.09211;42.35370;     -0.27148;3.33708
153.09211;42.68837;     -0.25527;3.33490
154.09211;43.02328;     -0.24027;3.33270
155.09211;43.35748;     -0.22605;3.33048
156.09211;43.69090;     -0.21466;3.32825
157.09211;44.02406;     -0.20567;3.32601
158.09211;44.35702;     -0.19852;3.32375
159.09211;44.68956;     -0.19240;3.32147
160.09211;45.02188;     -0.18671;3.31918
161.09211;45.35473;     -0.18198;3.31687
162.09211;45.68822;     -0.17691;3.31455
163.09211;46.02192;     -0.17058;3.31222
164.09211;46.35559;     -0.16350;3.30987
165.09211;46.68905;     -0.15567;3.30750
166.09211;47.02211;     -0.14649;3.30512
167.09211;47.35463;     -0.13641;3.30273
168.09211;47.68694;     -0.12503;3.30032
169.09211;48.01971;     -0.11343;3.29790
170.09211;48.35321;     -0.10068;3.29547
171.09211;48.68710;-8.704819e-02;3.29302
172.09211;49.02094;-7.206067e-02;3.29056
173.09211;49.35475;-5.659000e-02;3.28809
174.09211;49.68876;-4.070119e-02;3.28560
175.09211;50.02291;-2.457734e-02;3.28310
176.09211;50.35696;-8.917403e-03;3.28058
177.09211;50.69066; 7.797713e-03;3.27806
178.09211;51.02387; 2.339348e-02;3.27552
179.09211;51.35673; 3.870741e-02;3.27297
180.09211;51.68953; 5.299207e-02;3.27041
181.09211;52.02246; 6.628069e-02;3.26783
182.09211;52.35550; 7.920913e-02;3.26524
183.09211;52.68853; 9.097650e-02;3.26264
184.09211;53.02159;      0.10207;3.26003
185.09211;53.35475;      0.11147;3.25741
186.09211;53.68784;      0.12078;3.25478
187.09211;54.02085;      0.12872;3.25213
188.09211;54.35401;      0.13570;3.24948
189.09211;54.68739;      0.14180;3.24681
190.09211;55.02089;      0.14691;3.24413
191.09211;55.35432;      0.15191;3.24144
192.09211;55.68780;      0.15619;3.23874
193.09211;56.02157;      0.15955;3.23603
194.09211;56.35548;      0.16256;3.23331
195.09211;56.68927;      0.16556;3.23058
196.09211;57.02268;      0.16773;3.22784
197.09211;57.35554;      0.17027;3.22509
198.09211;57.68806;      0.17262;3.22233
199.09211;58.02054;      0.17455;3.21955
200.09211;58.35303;      0.17637;3.21677
201.09211;58.68559;      0.17810;3.21399
202.09211;59.01833;      0.17898;3.21119
203.09211;59.35129;      0.17984;3.20838
204.09211;59.68432;      0.18120;3.20556
205.09211;60.01733;      0.18211;3.20274
206.09211;60.35042;      0.18316;3.19990
207.09211;60.68372;      0.18343;3.19706
208.09211;61.01723;      0.18380;3.19421
209.09211;61.35071;      0.18458;3.19135
210.09211;61.68385;      0.18486;3.18848
211.09211;62.01682;      0.25436;3.18560
212.09211;62.35025;      0.24509;3.18272
213.09211;62.68426;      0.23792;3.17983
214.09211;63.01829;      0.23382;3.17693
215.09211;63.35191;      0.23082;3.17402
216.09211;63.68512;      0.22862;3.17111
217.09211;64.01806;      0.22621;3.16819
218.09211;64.35071;      0.22557;3.16526
219.09211;64.68289;      0.22300;3.16232